Workbook

Sheet Supuestos
A1: RetailIQ 360° — Supuestos del modelo financiero
A2: Escenario base — Proyecto actual (2 personas, trabajo remoto)
A4: TIPO DE CAMBIO Y PERÍODO
A5: Parámetro | B5: Valor | C5: Unidad | D5: Notas / Fuente
A6: Tipo de cambio USD/ARS | B6: 1400 | C6: ARS por USD | D6: Tipo de cambio referencia mayo 2025
A7: Inflación anual Argentina (ARS) | B7: 0.6 | C7: % anual | D7: Proyección base 2025 — actualizar según INDEC
A8: Duración del proyecto actual | B8: 8 | C8: semanas | D8: 21 abril al 15 junio 2025
A9: Horas semanales equipo total | B9: 12 | C9: hs/semana | D9: 6 hs por persona — trabajo part-time
A10: Horas totales del proyecto | B10: 96 | C10: horas
A12: PERSONAL
A13: Sueldo bruto mensual — Persona 1 | B13: 2000000 | C13: ARS/mes | D13: Sueldo actual empleo principal
A14: Sueldo bruto mensual — Persona 2 | B14: 2000000 | C14: ARS/mes | D14: Sueldo actual empleo principal
A15: Cargas sociales empleador | B15: 0.3 | C15: % s/bruto | D15: Aprox. 30% en Argentina (jubilación, obra social, ART)
A16: Costo laboral total — Persona 1 | B16: =B13*(1+B15) -> 2600000 | C16: ARS/mes | D16: Costo real para un empleador
A17: Costo laboral total — Persona 2 | B17: =B14*(1+B15) -> 2600000 | C17: ARS/mes | D17: Costo real para un empleador
A18: Costo laboral total equipo | B18: =B16+B17 -> 5200000 | C18: ARS/mes | D18: Suma ambas personas
A19: Costo laboral total equipo (USD) | B19: =B18/B6 -> 3714.2857 | C19: USD/mes | D19: Conversión al tipo de cambio
A20: Valor hora promedio equipo (ARS) | B20: =B13/160 -> 12500 | C20: ARS/hora | D20: Base: 160 hs laborales/mes por persona
A21: Valor hora promedio equipo (USD) | B21: =B20/B6 -> 8.9285714 | C21: USD/hora | D21: Conversión al tipo de cambio
A22: Horas dedicadas al proyecto/mes | B22: =B10/2 -> 48 | C22: hs/mes | D22: 12 hs semanales / 4 semanas (aprox)
A23: Costo oportunidad mensual equipo | B23: =B21*B22 -> 428.57143 | C23: USD/mes | D23: Horas × valor hora — lo que dejan de ganar
A24: Costo oportunidad total proyecto | B24: =B23*(B9/4) -> 1285.7143 | C24: USD | D24: Costo oportunidad por duración del proyecto
A28: HERRAMIENTAS Y LICENCIAS
A29: ChatGPT Plus | B29: 20 | C29: USD/mes | D29: 1 cuenta — uso compartido del equipo
A30: Claude Pro | B30: 20 | C30: USD/mes | D30: 1 cuenta — uso compartido del equipo
A31: Microsoft Office 365 | B31: 10 | C31: USD/mes | D31: Estimado plan Personal/Family — ajustar según plan
A32: Power BI Desktop | B32: 0 | C32: USD/mes | D32: Gratuito — versión Desktop sin publicación en nube
A33: GitHub | B33: 0 | C33: USD/mes | D33: Plan Free — repositorios públicos y privados limitados
A34: SQL Server Developer | B34: 0 | C34: USD/mes | D34: Gratuito para uso no productivo
A35: Python / Jupyter | B35: 0 | C35: USD/mes | D35: Open source — sin costo de licencia
A36: Google Drive | B36: 0 | C36: USD/mes | D36: Plan gratuito (15 GB) — suficiente para el proyecto
A37: Trello | B37: 0 | C37: USD/mes | D37: Plan Free — suficiente para equipos pequeños
A38: Total herramientas/mes | B38: =SUM(B29:B37) -> 50 | C38: USD/mes | D38: Costo real mensual en licencias
A40: GASTOS INDIRECTOS (fracción del gasto del hogar)
A41: Electricidad adicional (estimado) | B41: 5 | C41: USD/mes | D41: Computadoras encendidas +3-4 hs extra por día — fracción del gasto total del hogar
A42: Conectividad (fracción asignable) | B42: 8 | C42: USD/mes | D42: Aprox. 15-20% del costo de internet mensual del hogar por persona
A43: Consumibles (papel, impresión) | B43: 2 | C43: USD/mes | D43: Estimado conservador — documentación e impresión ocasional
A44: Total gastos indirectos/mes | B44: =SUM(B41:B43) -> 15 | C44: USD/mes | D44: Fracción del gasto doméstico atribuible al proyecto

Sheet Costos Fijos Recurrentes
A1: RetailIQ 360° — Costos fijos recurrentes del proyecto
A2: Escenario base — horizonte 5 años (expresado en USD constantes)
A4: Ítem de costo | B4: Año 1 (USD) | C4: Año 2 (USD) | D4: Año 3 (USD) | E4: Año 4 (USD) | F4: Año 5 (USD) | G4: Notas
A5: 1. COSTO OPORTUNIDAD DEL TIEMPO (el costo más importante)
A6: Valor hora equipo completo (USD) | B6: =Supuestos!B21*2 -> 17.857143 | C6: =Supuestos!B21*2 -> 17.857143 | D6: =Supuestos!B21*2 -> 17.857143 | E6: =Supuestos!B21*2 -> 17.857143 | G6: Valor hora × 2 personas — referencia para valorizar el tiempo
A7: Horas dedicadas al proyecto por mes | B7: =Supuestos!B22 -> 48 | C7: =Supuestos!B22 -> 48 | D7: =Supuestos!B22 -> 48 | E7: =Supuestos!B22 -> 48 | G7: 12 hs semanales ÷ 2 personas — ajustable en Supuestos
A8: Costo oportunidad mensual equipo (USD) | B8: =B6*B7 -> 857.14286 | C8: =C6*C7 -> 857.14286 | D8: =D6*D7 -> 857.14286 | E8: =E6*E7 -> 857.14286 | G8: Tiempo invertido valorizado a salario de mercado
A9: Costo oportunidad anual equipo (USD) | B9: =B8*12 -> 10285.714 | C9: =C8*12 -> 10285.714 | D9: =D8*12 -> 10285.714 | E9: =E8*12 -> 10285.714 | G9: Proyección anual del costo oportunidad
A11: 2. PERSONAL — hipótesis de crecimiento hacia producto comercializable
A12: Año 1-2: equipo fundador (sin sueldo formal) | B12: 0 | C12: 0 | D12: 0 | E12: 0 | G12: Las fundadoras trabajan a costo oportunidad — sin nómina formal en etapa MVP
A13: Año 3: primer contrato part-time (Data Engineer) | B13: 0 | C13: 0 | D13: 18000 | E13: 18000 | G13: USD 1.500/mes × 12 — soporte técnico para escalar la plataforma
A14: Año 4-5: comercial/ventas part-time | B14: 0 | C14: 0 | D14: 0 | E14: 12000 | G14: USD 1.000/mes × 12 — adquisición de clientes
A15: Subtotal personal (USD/año) | B15: =SUM(B12:B14) -> 0 | C15: =SUM(C12:C14) -> 0 | D15: =SUM(D12:D14) -> 18000 | E15: =SUM(E12:E14) -> 30000 | G15: Solo aplica si se formaliza la contratación
A17: 3. HERRAMIENTAS Y LICENCIAS
A18: ChatGPT Plus (1 cuenta compartida) | B18: 240 | C18: 240 | D18: 240 | E18: 240 | G18: USD 20/mes × 12
A19: Claude Pro (1 cuenta compartida) | B19: 240 | C19: 240 | D19: 240 | E19: 240 | G19: USD 20/mes × 12
A20: Microsoft Office 365 | B20: 120 | C20: 120 | D20: 120 | E20: 120 | G20: USD 10/mes × 12 — estimado plan Personal
A21: Power BI Desktop | B21: 0 | C21: 0 | D21: 0 | E21: 0 | G21: Gratuito en etapa actual
A22: Power BI Embedded (si se comercializa) | B22: 0 | C22: 0 | D22: 8820 | E22: 8820 | G22: USD 735/mes × 12 — SKU A1 mínimo si se publica para clientes en Año 3+
A23: GitHub Free | B23: 0 | C23: 0 | D23: 0 | E23: 0 | G23: Gratuito — actualizar si se requiere GitHub Teams
A24: SQL Server Developer | B24: 0 | C24: 0 | D24: 0 | E24: 0 | G24: Gratuito para uso no productivo
A25: Google Drive / Workspace | B25: 0 | C25: 0 | D25: 0 | E25: 144 | G25: USD 0 en etapa actual — USD 12/mes × 12 si se necesita Workspace Business
A26: Subtotal herramientas (USD/año) | B26: =SUM(B18:B25) -> 600 | C26: =SUM(C18:C25) -> 600 | D26: =SUM(D18:D25) -> 9420 | E26: =SUM(E18:E25) -> 9564 | G26: Costo real anual en licencias
A28: 4. INFRAESTRUCTURA TECNOLÓGICA
A29: Hosting cloud (AWS/Azure) — etapa actual | B29: 0 | C29: 0 | D29: 0 | E29: 0 | G29: No aplica en etapa académica — datos en local
A30: Hosting cloud — cuando se comercialice | B30: 0 | C30: 0 | D30: 1200 | E30: 2400 | G30: USD 100-400/mes × 12 según volumen de clientes
A31: Dominio y certificados SSL | B31: 0 | C31: 20 | D31: 20 | E31: 20 | G31: USD 20/año — necesario cuando se lance el producto
A32: Subtotal infraestructura (USD/año) | B32: =SUM(B29:B31) -> 0 | C32: =SUM(C29:C31) -> 20 | D32: =SUM(D29:D31) -> 1220 | E32: =SUM(E29:E31) -> 2420 | G32: Crece con la base de clientes
A34: 5. GASTOS INDIRECTOS DEL HOGAR (fracción atribuible al proyecto)
A35: Electricidad adicional (2 personas) | B35: 120 | C35: 120 | D35: 120 | E35: 120 | G35: USD 5/mes × 2 personas × 12
A36: Conectividad (fracción asignable) | B36: 192 | C36: 192 | D36: 192 | E36: 192 | G36: USD 8/mes × 2 personas × 12
A37: Consumibles (papel, impresión) | B37: 48 | C37: 48 | D37: 48 | E37: 48 | G37: USD 2/mes × 2 personas × 12
A38: Subtotal gastos indirectos (USD/año) | B38: =SUM(B35:B37) -> 360 | C38: =SUM(C35:C37) -> 360 | D38: =SUM(D35:D37) -> 360 | E38: =SUM(E35:E37) -> 360 | G38: Fracción del gasto doméstico atribuible al proyecto
A40: 6. LEGAL Y ADMINISTRATIVO (si se formaliza como empresa)
A41: Constitución de empresa (SRL/SA) | B41: 0 | C41: 0 | D41: 1500 | E41: 0 | G41: Costo único en Año 3 si se decide formalizar
A42: Asesoría contable / impositiva | B42: 0 | C42: 0 | D42: 1200 | E42: 1800 | G42: USD 100-150/mes × 12 — necesario al tener clientes pagos
A43: Registro de marca | B43: 0 | C43: 0 | D43: 800 | E43: 0 | G43: Costo único — propiedad intelectual de la plataforma
A44: Subtotal legal/admin (USD/año) | B44: =SUM(B41:B43) -> 0 | C44: =SUM(C41:C43) -> 0 | D44: =SUM(D41:D43) -> 3500 | E44: =SUM(E41:E43) -> 1800 | G44: Solo aplica a partir del lanzamiento comercial
A47: TOTAL COSTOS FIJOS RECURRENTES (sin costo oportunidad)
A48: TOTAL COSTOS DESEMBOLSABLES (USD/año) | B48: =B26+B32+B38+B44 -> 960 | C48: =C26+C32+C38+C44 -> 980 | D48: =D26+D32+D38+D44 -> 14500 | E48: =E26+E32+E38+E44 -> 14144 | G48: Dinero real que sale del bolsillo del equipo
...

Sheet Resumen VAN
A1: RetailIQ 360° — Estructura VAN a 5 años
A2: Escenario base — los ingresos proyectados deberán completarse según el modelo de negocio elegido
A4: PARÁMETROS DEL VAN
A5: Tasa de descuento anual | B5: 0.12 | C5: % | D5: 30% — refleja riesgo de startup tecnológica en Argentina operando en USD
A6: Inversión inicial (Año 0) | B6: 0 | C6: USD | D6: En etapa actual: USD 0 — el proyecto usa herramientas gratuitas y computadoras propias
A8: Concepto | B8: Año 1 | C8: Año 2 | D8: Año 3 | E8: Año 4 | F8: Año 5 | G8: Total 5 años
A9: INGRESOS PROYECTADOS (completar según modelo de negocio)
A10: Clientes activos (cantidad) | B10: 3 | C10: 8 | D10: 12 | E10: 15 | G10: Supuesto escenario base — ajustar según validación comercial
A11: Precio promedio mensual por cliente (USD) | B11: 300 | C11: 400 | D11: 600 | E11: 800 | G11: Crece con mejoras del producto y posicionamiento de marca
A12: MRR — ingresos mensuales recurrentes (USD) | B12: =B10*B11 -> 900 | C12: =C10*C11 -> 3200 | D12: =D10*D11 -> 7200 | E12: =E10*E11 -> 12000 | G12: Clientes × precio mensual promedio
A13: ARR — ingresos anuales recurrentes (USD) | B13: =B12*12 -> 10800 | C13: =C12*12 -> 38400 | D13: =D12*12 -> 86400 | E13: =E12*12 -> 144000 | G13: MRR × 12 meses
A14: Churn (clientes perdidos en el año) | B14: 0 | C14: 1 | D14: 2 | E14: 4 | G14: Estimado 5% anual sobre base de clientes — ajustar según retención real
A15: Ingresos netos ajustados por churn | B15: =B13 -> 10800 | C15: =C13-(C14*C11*12) -> 33600 | D15: =D13-(D14*D11*12) -> 72000 | E15: =E13-(E14*E11*12) -> 105600 | G15: ARR menos impacto del churn
A16: TOTAL INGRESOS NETOS (USD/año) | B16: =B15 -> 10800 | C16: =C15 -> 33600 | D16: =D15 -> 72000 | E16: =E15 -> 105600 | G16: =SUM(B16:F16) -> 222000
A18: COSTOS (traídos de hoja Costos Fijos Recurrentes)
A19: Costos desembolsables (USD/año) | B19: ='Costos Fijos Recurrentes'!B48 -> 960 | C19: ='Costos Fijos Recurrentes'!C48 -> 980 | D19: ='Costos Fijos Recurrentes'!D48 -> 14500 | E19: ='Costos Fijos Recurrentes'!E48 -> 14144 | G19: =SUM(B19:F19) -> 30584
A20: Costo oportunidad equipo (USD/año) | B20: ='Costos Fijos Recurrentes'!B9 -> 10285.714 | C20: ='Costos Fijos Recurrentes'!C9 -> 10285.714 | D20: ='Costos Fijos Recurrentes'!D9 -> 10285.714 | E20: ='Costos Fijos Recurrentes'!E9 -> 10285.714 | G20: =SUM(B20:F20) -> 41142.857
A21: TOTAL COSTOS (USD/año) | B21: =B19+B20 -> 11245.714 | C21: =C19+C20 -> 11265.714 | D21: =D19+D20 -> 24785.714 | E21: =E19+E20 -> 24429.714 | G21: =SUM(B21:F21) -> 71726.857
A23: FLUJO DE CAJA Y VALOR ACTUAL NETO
A24: Flujo de caja bruto (USD/año) | B24: =B16-B19 -> 9840 | C24: =C16-C19 -> 32620 | D24: =D16-D19 -> 57500 | E24: =E16-E19 -> 91456 | G24: Ingresos netos − costos desembolsables
A25: Flujo de caja económico (USD/año) | B25: =B16-B21 -> -445.71429 | C25: =C16-C21 -> 22334.286 | D25: =D16-D21 -> 47214.286 | E25: =E16-E21 -> 81170.286 | G25: Ingresos netos − total costos (incluye costo oportunidad)
A26: Factor de descuento (tasa 30%) | B26: =1/(1+$B$5)^1 -> 0.89285714 | C26: =1/(1+$B$5)^2 -> 0.79719388 | D26: =1/(1+$B$5)^3 -> 0.71178025 | E26: =1/(1+$B$5)^4 -> 0.63551808 | G26: Factor que trae el flujo futuro a valor presente
A27: Flujo de caja descontado — bruto | B27: =B24*B26 -> 8785.7143 | C27: =C24*C26 -> 26004.464 | D27: =D24*D26 -> 40927.364 | E27: =E24*E26 -> 58121.941 | G27: Flujo bruto traído a valor presente
A28: Flujo de caja descontado — económico | B28: =B25*B26 -> -397.95918 | C28: =C25*C26 -> 17804.756 | D28: =D25*D26 -> 33606.196 | E28: =E25*E26 -> 51585.184 | G28: Flujo económico traído a valor presente
A30: VAN BRUTO (sin costo oportunidad) | B30: =SUM(B27:F27)-B6 -> 133839.48 | G30: VAN considerando solo costos desembolsables reales — el más favorable
A31: VAN ECONÓMICO (con costo oportunidad) | B31: =SUM(B28:F28)-B6 -> 102598.18 | G31: VAN considerando el valor del tiempo invertido — el más conservador
A32: INTERPRETACIÓN DEL VAN
A33: VAN > 0 | B33: El proyecto genera valor por encima de la tasa de descuento exigida. El proyecto es financieramente conveniente.
A34: VAN = 0 | B34: El proyecto recupera exactamente la inversión a la tasa exigida. Punto de indiferencia.
A35: VAN < 0 | B35: El proyecto destruye valor a la tasa exigida. Replantear modelo de ingresos, reducir costos o ajustar la tasa de descuento.
A36: VAN Bruto > 0 pero VAN Económico < 0 | B36: El proyecto es rentable en términos de caja pero no compensa el tiempo invertido. Evaluar si existe un uso alternativo más rentable de ese tiempo.
